import { describe, it, expect, vi } from 'vitest';
import { render, screen } from '@/test/utils/test-utils';
import { ErrorBoundary } from '@/components/ErrorBoundary';
import React from 'react';

// Component that throws an error for testing
const ThrowError = ({ shouldThrow }: { shouldThrow: boolean }) => {
  if (shouldThrow) {
    throw new Error('Test error');
  }
  return <div>No error</div>;
};

// Mock console.error to avoid noise in tests
const originalError = console.error;
beforeAll(() => {
  console.error = vi.fn();
});

afterAll(() => {
  console.error = originalError;
});

describe('ErrorBoundary', () => {
  it('should render children when there is no error', () => {
    render(
      <ErrorBoundary>
        <ThrowError shouldThrow={false} />
      </ErrorBoundary>
    );

    expect(screen.getByText('No error')).toBeInTheDocument();
  });

  it('should render error UI when child component throws', () => {
    render(
      <ErrorBoundary>
        <ThrowError shouldThrow={true} />
      </ErrorBoundary>
    );

    expect(screen.getByText('Oops! Algo deu errado')).toBeInTheDocument();
    expect(screen.getByText('Encontramos um erro inesperado. Nossa equipe foi notificada.')).toBeInTheDocument();
  });

  it('should display custom fallback when provided', () => {
    const CustomFallback = () => <div>Custom error fallback</div>;

    render(
      <ErrorBoundary fallback={<CustomFallback />}>
        <ThrowError shouldThrow={true} />
      </ErrorBoundary>
    );

    expect(screen.getByText('Custom error fallback')).toBeInTheDocument();
    expect(screen.queryByText('Oops! Algo deu errado')).not.toBeInTheDocument();
  });

  it('should call onError callback when error occurs', () => {
    const onError = vi.fn();

    render(
      <ErrorBoundary onError={onError}>
        <ThrowError shouldThrow={true} />
      </ErrorBoundary>
    );

    expect(onError).toHaveBeenCalledWith(
      expect.any(Error),
      expect.objectContaining({
        componentStack: expect.any(String),
      })
    );
  });

  it('should show retry and home buttons in default fallback', () => {
    render(
      <ErrorBoundary>
        <ThrowError shouldThrow={true} />
      </ErrorBoundary>
    );

    expect(screen.getByText('Tentar Novamente')).toBeInTheDocument();
    expect(screen.getByText('Voltar ao InÃ­cio')).toBeInTheDocument();
  });

  it('should show error details in development mode', () => {
    const originalEnv = process.env.NODE_ENV;
    process.env.NODE_ENV = 'development';

    render(
      <ErrorBoundary>
        <ThrowError shouldThrow={true} />
      </ErrorBoundary>
    );

    expect(screen.getByText('Detalhes do Erro (desenvolvimento)')).toBeInTheDocument();

    process.env.NODE_ENV = originalEnv;
  });

  it('should not show error details in production mode', () => {
    const originalEnv = process.env.NODE_ENV;
    process.env.NODE_ENV = 'production';

    render(
      <ErrorBoundary>
        <ThrowError shouldThrow={true} />
      </ErrorBoundary>
    );

    expect(screen.queryByText('Detalhes do Erro (desenvolvimento)')).not.toBeInTheDocument();

    process.env.NODE_ENV = originalEnv;
  });
});

describe('withErrorBoundary HOC', () => {
  it('should wrap component with error boundary', () => {
    const { withErrorBoundary } = require('@/components/ErrorBoundary');
    
    const TestComponent = () => <div>Test Component</div>;
    const WrappedComponent = withErrorBoundary(TestComponent);

    render(<WrappedComponent />);

    expect(screen.getByText('Test Component')).toBeInTheDocument();
  });

  it('should catch errors in wrapped component', () => {
    const { withErrorBoundary } = require('@/components/ErrorBoundary');
    
    const ErrorComponent = () => {
      throw new Error('Wrapped component error');
    };
    const WrappedComponent = withErrorBoundary(ErrorComponent);

    render(<WrappedComponent />);

    expect(screen.getByText('Oops! Algo deu errado')).toBeInTheDocument();
  });
});